Workbook

Sheet INTRO
H3: Financial Management
H4: Assignment 3
J5: Amna Kauser
J6: Hifza Zaheer

Sheet sheet1
A1: LUCKY CORE INDUSTRIES LIMITED 01 JAN 2019 - 31 DEC 2025
A2: DATE | B2: PRICE (PKR) | C2: KSE-100 INDEX | D2: COMPANY RETURN | E2: INDEX RETURN
A3: 43467 | B3: 155.22 | C3: 37795.25 | D3: 0 | E3: 0
A4: 43468 | B4: 155.46 | C4: 37542.01 | D4: =(B4-B3)/B3 -> 0.0015461925 | E4: =(C4-C3)/C3 -> -0.0067003129
A5: 43469 | B5: 158.4 | C5: 37547.49 | D5: =(B5-B4)/B4 -> 0.018911617 | E5: =(C5-C4)/C4 -> 0.00014596981
A6: 43472 | B6: 156.8 | C6: 38562.4 | D6: =(B6-B5)/B5 -> -0.01010101 | E6: =(C6-C5)/C5 -> 0.027030036
A7: 43473 | B7: 157.46 | C7: 39052.5 | D7: =(B7-B6)/B6 -> 0.0042091837 | E7: =(C7-C6)/C6 -> 0.012709271
A8: 43474 | B8: 157.09 | C8: 38921.69 | D8: =(B8-B7)/B7 -> -0.0023498031 | E8: =(C8-C7)/C7 -> -0.0033495935
A9: 43475 | B9: 157.3 | C9: 39090.28 | D9: =(B9-B8)/B8 -> 0.0013368133 | E9: =(C9-C8)/C8 -> 0.004331518
A10: 43476 | B10: 154.63 | C10: 39049.08 | D10: =(B10-B9)/B9 -> -0.016973935 | E10: =(C10-C9)/C9 -> -0.0010539704
A11: 43479 | B11: 157 | C11: 39412.55 | D11: =(B11-B10)/B10 -> 0.015326909 | E11: =(C11-C10)/C10 -> 0.0093080298
A12: 43480 | B12: 154.61 | C12: 39614.17 | D12: =(B12-B11)/B11 -> -0.01522293 | E12: =(C12-C11)/C11 -> 0.0051156294
A13: 43481 | B13: 153.93 | C13: 39271.94 | D13: =(B13-B12)/B12 -> -0.0043981631 | E13: =(C13-C12)/C12 -> -0.0086390804
A14: 43482 | B14: 153.23 | C14: 39243.89 | D14: =(B14-B13)/B13 -> -0.0045475216 | E14: =(C14-C13)/C13 -> -0.00071425043
A15: 43483 | B15: 153.09 | C15: 39306.5 | D15: =(B15-B14)/B14 -> -0.00091365921 | E15: =(C15-C14)/C14 -> 0.0015954076
... A1679: 46022 | B1679: 288.34 | C1679: 174054.31 | D1679: =(B1679-B1678)/B1678 -> 0.0023639018 | E1679: =(C1679-C1678)/C1678 -> -0.0023985974
A1681: ANALYSIS
A1682: METRIC | B1682: LUCKY CORE (Company) | D1682: KSE-100 (Index)
A1683: AVERAGE | B1683: =AVERAGE(D3:D1679) -> 0.00053625938 | D1683: =AVERAGE(E3:E1679) -> 0.0009832075
A1684: STANDARD DEVIATION | B1684: =STDEV(D3:D1679) -> 0.018366021 | D1684: =STDEV(E3:E1679) -> 0.01200996
A1685: COEFFICIENT OF VARIATION | B1685: =B1684/B1683 -> 34.248392 | D1685: =D1684/D1683 -> 12.215082
A1687: REGRESSION ANALYSIS
A1688: BETA (Slope) | B1688: =SLOPE(D3:D1679,E3:E1679) -> 0.67435377

Sheet sheet2
A1: ALLIED BANK LIMITED 01 JAN 2019 - 31 DEC 2025
A3: DATE | B3: PRICE | C3: KSE-100 | D3: COMPANY RETURN | E3: INDEX RETURN
A4: 46022 | B4: 182.77 | C4: 174054.31 | D4: =(B4-B5)/B5 -> -0.0013114037 | E4: =(C4-C5)/C5 -> -0.0023985974
A5: 46021 | B5: 183.01 | C5: 174472.8 | D5: =(B5-B6)/B6 -> 0.0018612799 | E5: =(C5-C6)/C6 -> 0.0033149634
A6: 46020 | B6: 182.67 | C6: 173896.34 | D6: =(B6-B7)/B7 -> 0.0031852381 | E6: =(C6-C7)/C7 -> 0.0086751953
A7: 46017 | B7: 182.09 | C7: 172400.73 | D7: =(B7-B8)/B8 -> 0.0056331805 | E7: =(C7-C8)/C8 -> 0.0091933968
A8: 46015 | B8: 181.07 | C8: 170830.22 | D8: =(B8-B9)/B9 -> 0.0029356375 | E8: =(C8-C9)/C9 -> -0.0014234214
A9: 46014 | B9: 180.54 | C9: 171073.73 | D9: =(B9-B10)/B10 -> 0.0015533119 | E9: =(C9-C10)/C10 -> -0.00076201406
A10: 46013 | B10: 180.26 | C10: 171204.19 | D10: =(B10-B11)/B11 -> -0.0008314395 | E10: =(C10-C11)/C11 -> -0.0011685225
A11: 46010 | B11: 180.41 | C11: 171404.48 | D11: =(B11-B12)/B12 -> -0.011885201 | E11: =(C11-C12)/C12 -> -0.0032343444
A12: 46009 | B12: 182.58 | C12: 171960.66 | D12: =(B12-B13)/B13 -> 0.014558791 | E12: =(C12-C13)/C13 -> 0.0096692072
A13: 46008 | B13: 179.96 | C13: 170313.86 | D13: =(B13-B14)/B14 -> 0.00083421389 | E13: =(C13-C14)/C14 -> -0.00078288128
A14: 46007 | B14: 179.81 | C14: 170447.3 | D14: =(B14-B15)/B15 -> -0.0015547782 | E14: =(C14-C15)/C15 -> -0.0017221371
A15: 46006 | B15: 180.09 | C15: 170741.34 | D15: =(B15-B16)/B16 -> -0.0097872106 | E15: =(C15-C16)/C16 -> 0.0051618192
... A1698: 43467 | B1698: 105 | C1698: 37795.25 | D1698: =(B1698-B1699)/B1699 -> -0.022255331 | E1698: =(C1698-C1699)/C1699 -> -0.0052771678
A1699: 43466 | B1699: 107.39 | C1699: 37995.76 | D1699: 0 | E1699: 0
A1701: ANALYSIS
A1702: METRIC | B1702: Company | D1702: KSE-100 (Market)
A1703: Average | B1703: =AVERAGE(D4:D1699) -> 0.00047806971 | D1703: =AVERAGE(E4:E1699) -> 0.0009690857
A1704: Standard Deviation | B1704: =STDEV(D4:D1699) -> 0.018214188 | D1704: =STDEV(E4:E1699) -> 0.011944428
A1705: Coefficient of Variation (CV) | B1705: =B1704/ABS(B1703) -> 38.099438 | D1705: =D1704/ABS(D1703) -> 12.325461
A1707: REGRESSION ANALYSIS | B1707: =SLOPE(D4:D1699,E4:E1699) -> 0.56470357

Sheet sheet3
A1: National Foods Limited 01 Jan 2019 – 31 Dec 2025
A3: DATE | B3: PRICE | C3: KSE-100 | D3: COMPANY RETURN | E3: INDEX RETURN
A4: 12/31/2025 | B4: 396.21 | C4: 174054.31 | D4: =(B4-B5)/B5 -> 0.0079627557 | E4: =(C4-C5)/C5 -> -0.0023985974
A5: 12/30/2025 | B5: 393.08 | C5: 174472.8 | D5: =(B5-B6)/B6 -> 0.0040101147 | E5: =(C5-C6)/C6 -> 0.0033149634
A6: 12/29/2025 | B6: 391.51 | C6: 173896.34 | D6: =(B6-B7)/B7 -> -0.0072017244 | E6: =(C6-C7)/C7 -> 0.0086751953
A7: 12/26/2025 | B7: 394.35 | C7: 172400.73 | D7: =(B7-B8)/B8 -> 0.0023129321 | E7: =(C7-C8)/C8 -> 0.0091933968
A8: 12/24/2025 | B8: 393.44 | C8: 170830.22 | D8: =(B8-B9)/B9 -> 0.0095453146 | E8: =(C8-C9)/C9 -> -0.0014234214
A9: 12/23/2025 | B9: 389.72 | C9: 171073.73 | D9: =(B9-B10)/B10 -> -0.0013581038 | E9: =(C9-C10)/C10 -> -0.00076201406
A10: 12/22/2025 | B10: 390.25 | C10: 171204.19 | D10: =(B10-B11)/B11 -> -0.0030655256 | E10: =(C10-C11)/C11 -> -0.0011685225
A11: 12/19/2025 | B11: 391.45 | C11: 171404.48 | D11: =(B11-B12)/B12 -> -7.6632267e-05 | E11: =(C11-C12)/C12 -> -0.0032343444
A12: 12/18/2025 | B12: 391.48 | C12: 171960.66 | D12: =(B12-B13)/B13 -> 0.0010484057 | E12: =(C12-C13)/C13 -> 0.0096692072
A13: 12/17/2025 | B13: 391.07 | C13: 170313.86 | D13: =(B13-B14)/B14 -> -0.0019905576 | E13: =(C13-C14)/C14 -> -0.00078288128
A14: 12/16/2025 | B14: 391.85 | C14: 170447.3 | D14: =(B14-B15)/B15 -> 0.0045890376 | E14: =(C14-C15)/C15 -> -0.0017221371
A15: 12/15/2025 | B15: 390.06 | C15: 170741.34 | D15: =(B15-B16)/B16 -> -0.0022509848 | E15: =(C15-C16)/C16 -> 0.0051618192
A16: 46003 | B16: 390.94 | C16: 169864.53 | D16: =(B16-B17)/B17 -> -0.0026786398 | E16: =(C16-C17)/C17 -> 0.0076514452
A17: 45973 | B17: 391.99 | C17: 168574.69 | D17: =(B17-B18)/B18 -> -7.6526708e-05 | E17: =(C17-C18)/C18 -> -0.0051765144
A18: 45942 | B18: 392.02 | C18: 169451.86 | D18: =(B18-B19)/B19 -> -0.014381254 | E18: =(C18-C19)/C19 -> -2.6732542e-05
A19: 45912 | B19: 397.74 | C19: 169456.39 | D19: =(B19-B20)/B20 -> -0.0071640748 | E19: =(C19-C20)/C20 -> 0.0068515611
A20: 45881 | B20: 400.61 | C20: 168303.25 | D20: =(B20-B21)/B21 -> 0.027758537 | E20: =(C20-C21)/C21 -> 0.0072877025
A21: 45789 | B21: 389.79 | C21: 167085.58 | D21: =(B21-B22)/B22 -> 0.010604096 | E21: =(C21-C22)/C22 -> 0.0048232672
A22: 45759 | B22: 385.7 | C22: 166283.55 | D22: =(B22-B23)/B23 -> -0.0020440374 | E22: =(C22-C23)/C23 -> 0.00083186203
A23: 45728 | B23: 386.49 | C23: 166145.34 | D23: =(B23-B24)/B24 -> -0.0042766972 | E23: =(C23-C24)/C24 -> -0.0089293703
A24: 45700 | B24: 388.15 | C24: 167642.28 | D24: =(B24-B25)/B25 -> 0.0065347613 | E24: =(C24-C25)/C25 -> -0.0024985394
A25: 45669 | B25: 385.63 | C25: 168062.19 | D25: =(B25-B26)/B26 -> 0.00062274579 | E25: =(C25-C26)/C26 -> 0.0083063901
A26: 11/28/2025 | B26: 385.39 | C26: 166677.7 | D26: =(B26-B27)/B27 -> 0.015761314 | E26: =(C26-C27)/C27 -> 0.0078875485
A27: 11/27/2025 | B27: 379.41 | C27: 165373.31 | D27: =(B27-B28)/B28 -> 0.0042083532 | E27: =(C27-C28)/C28 -> 0.013388073
A28: 11/26/2025 | B28: 377.82 | C28: 163188.53 | D28: =(B28-B29)/B29 -> -0.0029819237 | E28: =(C28-C29)/C29 -> 0.0092524402
A29: 11/25/2025 | B29: 378.95 | C29: 161692.48 | D29: =(B29-B30)/B30 -> 0.00042239763 | E29: =(C29-C30)/C30 -> -0.0018002385
A30: 11/24/2025 | B30: 378.79 | C30: 161984.09 | D30: =(B30-B31)/B31 -> -0.008169464 | E30: =(C30-C31)/C31 -> -0.0007330528
A31: 11/21/2025 | B31: 381.91 | C31: 162102.92 | D31: =(B31-B32)/B32 -> -0.0052872845 | E31: =(C31-C32)/C32 -> -0.0051186674
A32: 11/20/2025 | B32: 383.94 | C32: 162936.94 | D32: =(B32-B33)/B33 -> -0.0026237174 | E32: =(C32-C33)/C33 -> 0.0043806712
A33: 11/19/2025 | B33: 384.95 | C33: 162226.28 | D33: =(B33-B34)/B34 -> -0.0025910092 | E33: =(C33-C34)/C34 -> 0.0080227978
A34: 11/18/2025 | B34: 385.95 | C34: 160935.13 | D34: =(B34-B35)/B35 -> -0.0013455119 | E34: =(C34-C35)/C35 -> -0.004651327
A35: 11/17/2025 | B35: 386.47 | C35: 161687.19 | D35: =(B35-B36)/B36 -> -0.01378008 | E35: =(C35-C36)/C36 -> -0.0015314769
A36: 11/14/2025 | B36: 391.87 | C36: 161935.19 | D36: =(B36-B37)/B37 -> 0.015286162 | E36: =(C36-C37)/C37 -> 0.0079528811
A37: 11/13/2025 | B37: 385.97 | C37: 160657.5 | D37: =(B37-B38)/B38 -> 0.0067031821 | E37: =(C37-C38)/C38 -> 0.015637174
A38: 46002 | B38: 383.4 | C38: 158183.95 | D38: =(B38-B39)/B39 -> -0.0079180252 | E38: =(C38-C39)/C39 -> 0.0019854881
A39: 45972 | B39: 386.46 | C39: 157870.5 | D39: =(B39-B40)/B40 -> -0.003866378 | E39: =(C39-C40)/C40 -> -0.022706117
A40: 45941 | B40: 387.96 | C40: 161538.41 | D40: =(B40-B41)/B41 -> -0.00064398135 | E40: =(C40-C41)/C41 -> 0.012190391
A41: 45849 | B41: 388.21 | C41: 159592.91 | D41: =(B41-B42)/B42 -> -0.0059660982 | E41: =(C41-C42)/C42 -> 0.0031182902
...

Sheet sheet4
A1: NESTLE PAKISTAN LIMITED 01 Jan 2019 – 31 Dec 2025
A3: DATE | B3: PRICE (PKR) | C3: KSE-100 | D3: COMPANY RETURN | E3: INDEX RETURN
A4: 46022 | B4: 7952.6 | C4: 174054.31 | D4: =(B4-B5)/B5 -> 0.00050323327 | E4: =(C4-C5)/C5 -> -0.0023985974
A5: 46021 | B5: 7948.6 | C5: 174472.8 | D5: =(B5-B6)/B6 -> -0.002547403 | E5: =(C5-C6)/C6 -> 0.0033149634
A6: 46020 | B6: 7968.9 | C6: 173896.34 | D6: =(B6-B7)/B7 -> -0.0046464571 | E6: =(C6-C7)/C7 -> 0.0086751953
A7: 46017 | B7: 8006.1 | C7: 172400.73 | D7: =(B7-B8)/B8 -> -0.00054927907 | E7: =(C7-C8)/C8 -> 0.0091933968
A8: 46015 | B8: 8010.5 | C8: 170830.22 | D8: =(B8-B9)/B9 -> 0.00068707058 | E8: =(C8-C9)/C9 -> -0.0014234214
A9: 46014 | B9: 8005 | C9: 171073.73 | D9: =(B9-B10)/B10 -> 0.00088773303 | E9: =(C9-C10)/C10 -> -0.00076201406
A10: 46013 | B10: 7997.9 | C10: 171204.19 | D10: =(B10-B11)/B11 -> 0.0018915669 | E10: =(C10-C11)/C11 -> -0.0011685225
A11: 46010 | B11: 7982.8 | C11: 171404.48 | D11: =(B11-B12)/B12 -> -0.00027551659 | E11: =(C11-C12)/C12 -> -0.0032343444
A12: 46009 | B12: 7985 | C12: 171960.66 | D12: =(B12-B13)/B13 -> -0.001875 | E12: =(C12-C13)/C13 -> 0.0096692072
A13: 46008 | B13: 8000 | C13: 170313.86 | D13: =(B13-B14)/B14 -> 0.0061627468 | E13: =(C13-C14)/C14 -> -0.00078288128
A14: 46007 | B14: 7951 | C14: 170447.3 | D14: =(B14-B15)/B15 -> -0.006261639 | E14: =(C14-C15)/C15 -> -0.0017221371
A15: 46006 | B15: 8001.1 | C15: 170741.34 | D15: =(B15-B16)/B16 -> 0.0001375 | E15: =(C15-C16)/C16 -> 0.0051618192
... A1455: 43467 | B1455: 8930 | C1455: 40887.62 | D1455: =(B1455-B1456)/B1456 -> -0.05 | E1455: =(C1455-C1456)/C1456 -> 0.00095694998
A1456: 43466 | B1456: 9400 | C1456: 40848.53 | D1456: 0 | E1456: 0
A1463: ANALYSIS
A1464: METRIC | B1464: Company | D1464: KSE-100 (Market)
A1465: AVERAGE | B1465: =AVERAGE(D3:D1454) -> 0.0001339079 | D1465: =AVERAGE(E3:E1454) -> 0.0010707704
A1466: STANDARD DEVIATION | B1466: =_xlfn.STDEV.S(D3:D1454) -> 0.020733258 | D1466: =_xlfn.STDEV.S(E3:E1454) -> 0.011995315
A1467: COEFFICIENT OF VARIATION | B1467: =B1466/B1465 -> 154.83222 | D1467: =D1466/D1465 -> 11.202509
A1469: Regression analysis | B1469: =SLOPE(D3:D1454,E3:E1454) -> 0.0055777467

Sheet sheet5
B53: INTERPRETATIONS
C55: The beta values of the selected companies were estimated using regression analysis of their returns against the KSE-100 index.
B56: The results show that all companies have beta values less than 1, indicating that they are less volatile than the overall market.
C58: Lucky Core Industries has a beta of 0.674, which means it is moderately sensitive to market movements but still less risky than the market.
C59: Allied Bank Limited has a beta of 0.565, indicating relatively stable performance with lower fluctuations compared to the market.
C60: National Foods Limited shows a beta of 0.686, suggesting moderate risk and some responsiveness to market changes.
C62: Nestlé Pakistan has a beta of 0.006, which is extremely low, indicating that its returns are almost independent of market movements and it is highly stable.
C64: These beta values are consistent with the scatter plots, where the slopes of the regression lines are relatively flat, showing low sensitivity to the KSE-100 index.
C66: Overall, the analysis suggests that all selected companies are defensive stocks with lower risk and lower volatility compared to the market.

Sheet sheet6
A1: PORTFOLIO BETA OF COMPANIES | F1: NEW PORTFOLIO BETA
A2: Weight 1 | C2: 0.3 | F2: Weight 1 | H2: 0.25 | I2: Beta 1 | J2: =C6 -> 0.50947309
A3: Weight 2 | C3: 0.3 | F3: Weight 2 | H3: 0.15 | I3: Beta 2 | J3: 0.769
A4: Weight 3 | C4: 0.2 | F4: Weight 3 | H4: 0.4 | I4: Beta 3 | J4: 0.985
A5: Weight 4 | C5: 0.1 | F5: Weight 4 | H5: 0.2 | I5: Beta 4 | J5: 1.423
A6: Portfolio Beta | C6: =C2*sheet1!B1688+C3*sheet2!B1707+C4*sheet3!B1720+C5*sheet4!B1469 -> 0.50947309 | F6: Portfolio Beta | H6: =H2*J2+H3*J3+H4*J4+H5*J5 -> 0.92131827
A8: CAPM | F8: CAPM
A9: Risk free rate | C9: 0.1189 | F9: Risk free rate | H9: 0.1189
A10: Portfolio Beta | C10: =C6 -> 0.50947309 | F10: Portfolio Beta | H10: =H6 -> 0.92131827
A11: Market Return | C11: =(1 + sheet4!D1465)^252 - 1 -> 0.30955814 | F11: Market Return | H11: =C11 -> 0.30955814
A12: Required Rate of Return | C12: =C9+C10*(C11-C9) -> 0.21603519 | F12: Required Rate of Return | H12: =H9+H10*(H11-H9) -> 0.29455683
C15: Asset | D15: Beta | E15: Required Return | F15: Actual Return | G15: Intrepretation
C16: Lucky core | D16: =sheet1!B1688 -> 0.67435377 | E16: =C$9+(C$11-C$9)*D16 -> 0.24747103 | F16: =(1 + sheet1!B1683)^252 - 1 -> 0.14465255 | G16: undervalued
C17: Allied bank | D17: =sheet2!B1707 -> 0.56470357 | E17: =C$9+(C$11-C$9)*D17 -> 0.22656533 | F17: =(1 + sheet2!B1703)^252 - 1 -> 0.12799845 | G17: undervalued
C18: National foods | D18: =sheet3!B1720 -> 0.68599055 | E18: =C$9+(C$11-C$9)*D18 -> 0.24968968 | F18: =(1 +sheet3!B1716)^252 - 1 -> 0.28992933 | G18: overvalued
C19: Nestle Pakistan | D19: =sheet4!B1469 -> 0.0055777467 | E19: =C$9+(C$11-C$9)*D19 -> 0.11996344 | F19: =(1 + sheet4!B1465)^252 - 1 -> 0.034318268 | G19: undervalued
C20: Risk free rate | D20: 0 | E20: =C9 -> 0.1189
C21: Market return | D21: 1 | E21: =C11 -> 0.30955814
